
local _ = {name = "air", param1 = 0}
local t = {name = "chemistry:ionized_trunk", param1 = 255}
local T = {name = "chemistry:ionized_trunk", param1 = 255, force_place = true}
local L = {name = "chemistry:ionized_leaves", param1 = 255}
local l = {name = "chemistry:ionized_leaves", param1 = 150}

chemistry.ionized_tree = {

	size = {x = 5, y = 7, z = 5},

	yslice_prob = {
		{ypos = 2, prob = 127},
		{ypos = 3, prob = 127}
	},

	data = {

	_,_,_,_,_,
	_,_,_,_,_,
	_,_,_,_,_,
	l,L,L,L,l,
	l,L,L,L,l,
	_,_,_,_,_,
	_,_,_,_,_,

	_,_,_,_,_,
	_,_,_,_,_,
	_,_,_,_,_,
	L,L,L,L,L,
	L,L,L,L,L,
	_,l,L,l,_,
	_,_,L,_,_,

	_,_,T,_,_,
	_,_,T,_,_,
	_,_,T,_,_,
	L,L,T,L,L,
	L,L,t,L,L,
	_,L,t,L,_,
	_,L,L,L,_,

	_,_,_,_,_,
	_,_,_,_,_,
	_,_,_,_,_,
	L,L,L,L,L,
	L,L,L,L,L,
	_,l,L,l,_,
	_,_,L,_,_,

	_,_,_,_,_,
	_,_,_,_,_,
	_,_,_,_,_,
	l,L,L,L,l,
	l,L,L,L,l,
	_,_,_,_,_,
	_,_,_,_,_,

	}
}

local _ = {name = "air", prob = 0}
local T = {name = "chemistry:anthracite_trunk", prob = 255}
local t = {name = "chemistry:anthracite_trunk", prob = 127}
local M = {name = "chemistry:anthracite_trunk", prob = 255, force_place = true}
local L = {name = "chemistry:anthracite_leaves", prob = 255}

chemistry.anthracite_tree = {

	size = {x = 9, y = 19, z = 9},

	yslice_prob = {
		{ypos = 1, prob = 254},
		{ypos = 3, prob = 254},
		{ypos = 5, prob = 254}
	},

	data = {

	_,_,_,_,_,_,_,_,_,
	_,_,_,_,_,_,_,_,_,
	_,_,_,_,_,_,_,_,_,
	_,_,_,_,_,_,_,_,_,
	_,_,_,_,_,_,_,_,_,
	_,_,_,_,_,_,_,_,_,
	_,_,_,_,_,_,_,_,_,
	_,_,_,_,_,_,_,_,_,
	_,_,_,_,_,_,_,_,_,
	_,_,_,_,_,_,_,_,_,
	_,_,_,_,_,_,_,_,_,
	_,_,_,_,_,_,_,_,_,
	_,_,_,_,_,_,_,_,_,
	_,_,_,_,L,L,_,_,_,
	_,_,_,_,_,_,_,_,_,
	_,_,_,_,_,_,_,_,_,
	_,_,_,_,_,_,_,_,_,
	_,_,_,_,_,_,_,_,_,
	_,_,_,_,_,_,_,_,_,

	_,_,_,_,_,_,_,_,_,
	_,_,_,_,_,_,_,_,_,
	_,_,_,_,_,_,_,_,_,
	_,_,_,_,_,_,_,_,_,
	_,_,_,_,_,_,_,_,_,
	_,_,_,_,_,_,_,_,_,
	_,_,_,_,_,_,_,_,_,
	_,_,_,_,_,_,_,_,_,
	_,_,_,_,_,_,_,_,_,
	_,_,_,_,_,_,_,_,_,
	_,_,_,_,_,_,_,_,_,
	_,_,_,_,_,_,_,_,_,
	_,_,_,_,_,_,_,_,_,
	_,_,_,L,T,L,_,_,_,
	_,_,_,_,L,_,_,_,_,
	_,_,_,_,_,_,_,_,_,
	_,_,_,_,_,_,_,_,_,
	_,_,_,_,L,L,_,_,_,
	_,_,_,_,_,_,_,_,_,

	_,_,_,_,_,_,_,_,_,
	_,_,_,_,_,_,_,_,_,
	_,_,_,_,_,_,_,_,_,
	_,_,_,_,_,_,_,_,_,
	_,_,_,_,_,_,_,_,_,
	_,_,_,_,_,_,_,_,_,
	_,_,_,_,_,_,_,_,_,
	_,_,_,_,_,_,_,_,_,
	_,_,_,_,_,_,_,_,_,
	_,_,_,_,_,_,_,_,_,
	_,_,_,_,_,_,_,_,_,
	_,_,_,_,_,_,_,_,_,
	_,_,_,_,t,_,_,_,_,
	_,_,_,L,T,L,_,_,_,
	_,_,_,_,L,_,_,_,_,
	_,_,_,_,_,_,_,_,_,
	_,_,_,_,_,_,_,_,_,
	_,_,_,L,t,L,_,_,_,
	_,_,_,_,L,_,_,_,_,

	_,_,_,_,_,_,_,_,_,
	_,_,_,_,_,_,_,_,_,
	_,_,_,_,_,_,_,_,_,
	_,_,_,_,_,_,_,_,_,
	_,_,_,_,T,_,_,_,_,
	_,_,_,_,_,_,_,_,_,
	_,_,_,_,_,_,_,_,_,
	_,_,_,_,_,_,_,_,_,
	_,_,_,_,T,_,_,_,_,
	_,_,_,_,L,L,_,_,_,
	_,_,_,_,_,_,L,L,_,
	_,_,_,L,_,_,_,_,_,
	L,L,L,L,T,L,_,_,_,
	_,_,_,_,_,L,_,_,_,
	_,_,_,_,L,_,L,L,_,
	_,_,L,L,L,_,_,_,_,
	L,L,L,L,T,L,_,_,_,
	_,_,_,L,T,L,_,_,_,
	_,_,_,_,L,_,_,_,_,

	_,_,_,_,M,_,_,_,_,
	_,_,_,_,M,_,_,_,_,
	_,_,_,_,M,_,_,_,_,
	_,_,_,T,M,_,_,_,_,
	_,_,_,_,M,_,_,_,_,
	_,_,_,_,T,T,_,_,_,
	_,_,_,_,T,_,_,_,_,
	_,_,_,T,T,_,_,_,_,
	_,_,_,_,T,_,_,_,_,
	_,_,_,_,T,T,t,_,_,
	_,_,_,_,T,_,T,T,L,
	_,_,t,T,T,_,L,L,_,
	L,T,T,_,T,_,_,_,_,
	_,L,L,_,T,T,t,_,_,
	_,_,_,_,T,L,T,T,L,
	_,_,t,T,T,L,L,L,_,
	L,T,T,L,T,L,_,_,_,
	_,L,L,_,L,L,_,_,_,
	_,_,_,_,_,_,_,_,_,

	_,_,_,_,_,_,_,_,_,
	_,_,_,_,_,_,_,_,_,
	_,_,_,_,_,_,_,_,_,
	_,_,_,_,_,_,_,_,_,
	_,_,_,_,_,_,_,_,_,
	_,_,_,_,_,_,_,_,_,
	_,_,_,_,T,_,_,_,_,
	_,_,_,_,_,_,_,_,_,
	_,_,_,_,_,_,_,_,_,
	_,_,_,_,_,L,_,_,_,
	_,_,_,_,T,L,L,L,L,
	_,_,_,L,_,_,_,_,_,
	_,L,L,_,_,_,_,_,_,
	_,_,_,_,_,L,_,_,_,
	_,_,_,L,T,L,L,L,L,
	_,_,L,L,L,_,_,_,_,
	_,L,L,_,L,_,_,_,_,
	_,_,_,_,L,_,_,_,_,
	_,_,_,_,_,_,_,_,_,

	_,_,_,_,_,_,_,_,_,
	_,_,_,_,_,_,_,_,_,
	_,_,_,_,_,_,_,_,_,
	_,_,_,_,_,_,_,_,_,
	_,_,_,_,_,_,_,_,_,
	_,_,_,_,_,_,_,_,_,
	_,_,_,_,_,_,_,_,_,
	_,_,_,_,_,_,_,_,_,
	_,_,_,_,_,_,_,_,_,
	_,_,_,_,_,_,_,_,_,
	_,_,_,_,t,_,_,_,_,
	_,_,_,L,T,L,_,_,_,
	_,_,_,_,_,_,_,_,_,
	_,_,_,_,_,_,_,_,_,
	_,_,_,L,t,L,_,_,_,
	_,_,_,L,T,L,_,_,_,
	_,_,_,_,L,_,_,_,_,
	_,_,_,_,_,_,_,_,_,
	_,_,_,_,_,_,_,_,_,

	_,_,_,_,_,_,_,_,_,
	_,_,_,_,_,_,_,_,_,
	_,_,_,_,_,_,_,_,_,
	_,_,_,_,_,_,_,_,_,
	_,_,_,_,_,_,_,_,_,
	_,_,_,_,_,_,_,_,_,
	_,_,_,_,_,_,_,_,_,
	_,_,_,_,_,_,_,_,_,
	_,_,_,_,_,_,_,_,_,
	_,_,_,_,_,_,_,_,_,
	_,_,_,_,_,_,_,_,_,
	_,_,_,L,T,L,_,_,_,
	_,_,_,L,L,_,_,_,_,
	_,_,_,_,_,_,_,_,_,
	_,_,_,_,_,_,_,_,_,
	_,_,_,L,T,L,_,_,_,
	_,_,_,_,L,_,_,_,_,
	_,_,_,_,_,_,_,_,_,
	_,_,_,_,_,_,_,_,_,

	_,_,_,_,_,_,_,_,_,
	_,_,_,_,_,_,_,_,_,
	_,_,_,_,_,_,_,_,_,
	_,_,_,_,_,_,_,_,_,
	_,_,_,_,_,_,_,_,_,
	_,_,_,_,_,_,_,_,_,
	_,_,_,_,_,_,_,_,_,
	_,_,_,_,_,_,_,_,_,
	_,_,_,_,_,_,_,_,_,
	_,_,_,_,_,_,_,_,_,
	_,_,_,_,_,_,_,_,_,
	_,_,_,L,L,_,_,_,_,
	_,_,_,_,_,_,_,_,_,
	_,_,_,_,_,_,_,_,_,
	_,_,_,_,_,_,_,_,_,
	_,_,_,L,L,_,_,_,_,
	_,_,_,_,_,_,_,_,_,
	_,_,_,_,_,_,_,_,_,
	_,_,_,_,_,_,_,_,_,

	}
}

local _ = {name="air", prob=0}
local L = {name="chemistry:chestnut_leaves", prob=255}
local T = {name="chemistry:chestnut_trunk", prob=255, force_place=true}
local F = {name="chemistry:chestnut_fruit", prob=115}

chemistry.chestnut_tree = {

	size = {x = 7, y = 9, z = 7},

	yslice_prob = {
		{ypos = 2, prob = 127},
		{ypos = 2, prob = 127}
	},

	data = {

      _,_,_,_,_,_,_,
      _,_,_,_,_,_,_,
      _,_,_,_,_,_,_,
      _,_,_,_,_,_,_,
      _,_,_,_,_,_,_,
      _,_,L,L,L,_,_,
      _,_,_,L,_,_,_,
      _,_,_,_,_,_,_,
      _,_,_,_,_,_,_,

      _,_,_,_,_,_,_,
      _,_,_,_,_,_,_,
      _,_,_,_,_,_,_,
      _,_,_,_,_,_,_,
      _,_,_,_,_,_,_,
      _,L,L,_,L,L,_,
      _,L,L,L,L,L,_,
      _,_,L,L,L,_,_,
      _,_,_,_,_,_,_,

      _,_,_,_,_,_,_,
      _,_,_,_,_,_,_,
      _,_,_,_,_,_,_,
      _,_,_,_,_,_,_,
      _,_,_,_,_,_,_,
      L,L,T,_,F,L,L,
      _,L,L,_,T,L,_,
      _,L,L,L,L,L,_,
      _,_,_,L,_,_,_,

      _,_,_,T,_,_,_,
      _,_,_,T,_,_,_,
      _,_,_,T,_,_,_,
      _,_,_,T,_,_,_,
      _,_,_,T,_,_,_,
      L,F,_,T,_,_,L,
      L,L,_,_,_,L,L,
      _,L,L,L,L,L,_,
      _,_,L,L,L,_,_,

      _,_,_,_,_,_,_,
      _,_,_,_,_,_,_,
      _,_,_,_,_,_,_,
      _,_,_,_,_,_,_,
      _,_,_,_,_,F,_,
      L,L,_,_,T,L,L,
      _,L,T,_,L,L,_,
      _,L,L,L,L,L,_,
      _,_,_,L,_,_,_,

      _,_,_,_,_,_,_,
      _,_,_,_,_,_,_,
      _,_,_,_,_,_,_,
      _,_,_,_,_,_,_,
      _,_,_,_,_,_,_,
      _,L,L,F,L,L,_,
      _,L,L,L,L,L,_,
      _,_,L,L,L,_,_,
      _,_,_,_,_,_,_,

      _,_,_,_,_,_,_,
      _,_,_,_,_,_,_,
      _,_,_,_,_,_,_,
      _,_,_,_,_,_,_,
      _,_,_,_,_,_,_,
      _,_,L,L,L,_,_,
      _,_,_,L,_,_,_,
      _,_,_,_,_,_,_,
      _,_,_,_,_,_,_,

   }
}

local _ = {name="air", prob=0}
local L = {name="chemistry:dead_leaves", prob=255}
local T = {name="default:tree", prob=255, force_place=true}
local F = {name="air", prob=0}
local D = {name="chemistry:ash", prob=255}

chemistry.ash_tree = {

	size = {x = 7, y = 10, z = 7},

	yslice_prob = {
		{ypos = 2, prob = 127},
		{ypos = 2, prob = 127}
	},

	data = {

      _,_,_,_,_,_,_,
      _,_,_,_,_,_,_,
      _,_,_,_,_,_,_,
      _,_,_,_,_,_,_,
      _,_,_,_,_,_,_,
      _,_,L,L,L,_,_,
      _,_,D,L,D,_,_,
      _,_,_,D,_,_,_,
      _,_,_,_,_,_,_,
      _,_,_,_,_,_,_,

      _,_,_,_,_,_,_,
      _,_,_,_,_,_,_,
      _,_,_,_,_,_,_,
      _,_,_,_,_,_,_,
      _,_,_,_,_,_,_,
      _,L,L,_,L,L,_,
      _,L,L,L,L,L,_,
      _,D,L,L,L,D,_,
      _,_,D,D,D,_,_,
      _,_,_,_,_,_,_,

      _,_,_,_,_,_,_,
      _,_,_,_,_,_,_,
      _,_,_,_,_,_,_,
      _,_,_,_,_,_,_,
      _,_,_,_,_,_,_,
      L,L,T,_,F,L,L,
      D,L,L,_,T,L,D,
      _,L,L,L,L,L,_,
      _,D,D,L,D,D,_,
      _,_,_,D,_,_,_,

      _,_,_,T,_,_,_,
      _,_,_,T,_,_,_,
      _,_,_,T,_,_,_,
      _,_,_,T,_,_,_,
      _,_,_,T,_,_,_,
      L,F,_,T,_,_,L,
      L,L,_,D,_,L,L,
      D,L,L,L,L,L,D,
      _,D,L,L,L,D,_,
      _,_,D,D,D,_,_,

      _,_,_,_,_,_,_,
      _,_,_,_,_,_,_,
      _,_,_,_,_,_,_,
      _,_,_,_,_,_,_,
      _,_,_,_,_,F,_,
      L,L,_,_,T,L,L,
      D,L,T,_,L,L,D,
      _,L,L,L,L,L,_,
      _,D,D,L,D,D,_,
      _,_,_,D,_,_,_,

      _,_,_,_,_,_,_,
      _,_,_,_,_,_,_,
      _,_,_,_,_,_,_,
      _,_,_,_,_,_,_,
      _,_,_,_,_,_,_,
      _,L,L,F,L,L,_,
      _,L,L,L,L,L,_,
      _,D,L,L,L,D,_,
      _,_,D,D,D,_,_,
      _,_,_,_,_,_,_,

      _,_,_,_,_,_,_,
      _,_,_,_,_,_,_,
      _,_,_,_,_,_,_,
      _,_,_,_,_,_,_,
      _,_,_,_,_,_,_,
      _,_,L,L,L,_,_,
      _,_,D,L,D,_,_,
      _,_,_,D,_,_,_,
      _,_,_,_,_,_,_,
      _,_,_,_,_,_,_,

   }
}
