
local _ = {name = "air", prob = 0}
local d = {name = "chemistry:alkaline_sand", prob = 245}
local s = {name = "chemistry:alkaline_sandstone", prob = 255}
local l = {name = "chemistry:cesium_block", prob = 255, force_place = true}
local f = {name = "chemistry:cesium_block", prob = 255}
local o = {name = "chemistry:alkaline_sandstone", prob = 215}

chemistry.cesium_volcano = {

	size = {x = 17, y = 4, z = 15},

	yslice_prob = {
		{ypos = 0, prob = 127},
		{ypos = 1, prob = 127},
	},

	data = {

	_,_,_,_,_,_,_,_,_,_,_,_,_,_,_,_,_,
	_,_,_,_,_,_,_,_,_,_,_,_,_,_,_,_,_,
	_,_,_,_,_,_,_,_,_,_,_,_,_,_,_,_,_,
	_,_,_,_,_,_,_,_,_,_,_,_,_,_,_,_,_,

	_,_,_,_,d,d,d,d,_,_,d,_,_,_,_,_,_,
	_,_,_,_,_,_,_,_,_,_,_,_,_,_,_,_,_,
	_,_,_,_,_,_,_,_,_,_,_,_,_,_,_,_,_,
	_,_,_,_,_,_,_,_,_,_,_,_,_,_,_,_,_,

	_,_,_,d,s,s,s,s,d,d,s,d,d,_,_,_,_,
	_,_,_,_,s,s,s,s,_,_,s,_,_,_,_,_,_,
	_,_,_,_,_,_,_,_,_,_,_,_,_,_,_,_,_,
	_,_,_,_,_,_,_,_,_,_,_,_,_,_,_,_,_,

	_,_,d,s,o,o,o,o,s,s,o,s,s,d,_,_,_,
	_,_,_,s,f,f,s,f,s,s,f,s,s,_,_,_,_,
	_,_,_,_,s,s,_,s,_,_,s,_,_,_,_,_,_,
	_,_,_,_,_,_,_,_,_,_,_,_,_,_,_,_,_,

	_,d,s,o,s,s,s,s,o,o,s,o,o,s,d,_,_,
	_,_,s,l,l,l,l,f,s,f,f,l,l,s,_,_,_,
	_,_,_,s,f,f,s,s,o,s,o,s,s,_,_,_,_,
	_,_,_,_,o,o,o,_,_,_,o,_,_,_,_,_,_,

	_,d,s,o,s,o,o,o,s,s,o,s,s,o,s,d,_,
	_,_,s,f,l,l,l,l,l,l,l,l,l,l,s,_,_,
	_,_,_,s,f,f,f,f,f,f,l,f,l,s,_,_,_,
	_,_,_,_,o,_,_,o,o,o,_,o,o,_,_,_,_,

	_,d,s,o,s,o,s,s,o,o,s,o,s,o,s,d,_,
	_,_,s,s,l,l,l,l,l,l,l,l,l,l,s,_,_,
	_,_,_,_,o,f,f,f,f,f,f,f,l,s,_,_,_,
	_,_,_,_,_,_,_,_,_,_,_,_,o,_,_,_,_,

	_,_,d,s,o,s,o,s,s,s,s,o,s,o,s,d,_,
	_,_,_,s,l,l,l,l,l,l,l,l,l,l,s,_,_,
	_,_,_,s,f,f,f,f,f,f,f,f,l,s,_,_,_,
	_,_,_,_,o,_,_,_,_,_,_,_,s,_,_,_,_,

	_,d,s,o,s,o,o,o,o,o,o,s,o,s,d,_,_,
	_,_,s,l,l,l,l,l,l,l,l,l,l,s,_,_,_,
	_,_,_,s,f,f,f,f,f,f,f,l,s,_,_,_,_,
	_,_,_,_,o,_,_,_,_,_,_,_,o,_,_,_,_,

	_,d,s,o,s,s,s,s,s,s,o,s,o,s,d,_,_,
	_,_,s,l,l,l,l,l,l,l,l,l,l,s,_,_,_,
	_,_,_,s,f,f,f,f,l,l,f,l,s,_,_,_,_,
	_,_,_,_,o,o,_,_,_,o,_,o,_,_,_,_,_,

	_,_,d,s,o,o,o,o,o,o,s,o,s,d,_,_,_,
	_,_,_,s,s,l,f,f,f,f,l,l,s,_,_,_,_,
	_,_,_,_,s,s,s,s,s,s,f,s,_,_,_,_,_,
	_,_,_,_,_,s,o,o,o,_,s,_,_,_,_,_,_,

	_,_,_,d,s,s,s,s,s,s,o,s,d,_,_,_,_,
	_,_,_,_,s,s,s,s,s,s,l,s,_,_,_,_,_,
	_,_,_,_,_,_,_,_,_,_,s,_,_,_,_,_,_,
	_,_,_,_,_,_,_,_,_,_,_,_,_,_,_,_,_,

	_,_,_,_,d,d,d,d,d,d,s,s,d,_,_,_,_,
	_,_,_,_,_,_,_,_,_,_,s,s,_,_,_,_,_,
	_,_,_,_,_,_,_,_,_,_,_,_,_,_,_,_,_,
	_,_,_,_,_,_,_,_,_,_,_,_,_,_,_,_,_,

	_,_,_,_,_,_,_,_,_,_,d,d,_,_,_,_,_,
	_,_,_,_,_,_,_,_,_,_,_,_,_,_,_,_,_,
	_,_,_,_,_,_,_,_,_,_,_,_,_,_,_,_,_,
	_,_,_,_,_,_,_,_,_,_,_,_,_,_,_,_,_,

	_,_,_,_,_,_,_,_,_,_,_,_,_,_,_,_,_,
	_,_,_,_,_,_,_,_,_,_,_,_,_,_,_,_,_,
	_,_,_,_,_,_,_,_,_,_,_,_,_,_,_,_,_,
	_,_,_,_,_,_,_,_,_,_,_,_,_,_,_,_,_,

	}
}

local _ = {name = "air", prob = 0}
local d = {name = "chemistry:stone", prob = 255}
local s = {name = "chemistry:stone_cobble_glow2", prob = 255, force_place = true}
local l = {name = "chemistry:msteel", prob = 255, force_place = true}
local f = {name = "chemistry:msteel_flowing", prob = 255}
local o = {name = "default:steelblock", prob = 215}

chemistry.metal_volcano1 = {

	size = {x = 17, y = 5, z = 15},

	yslice_prob = {
		{ypos = 0, prob = 127},
		{ypos = 1, prob = 127},
	},

	data = {

	_,_,_,_,_,_,d,d,d,d,_,_,_,_,_,_,_,
	_,_,_,_,_,_,_,_,_,_,_,_,_,_,_,_,_,
	_,_,_,_,_,_,_,_,_,_,_,_,_,_,_,_,_,
	_,_,_,_,_,_,_,_,_,_,_,_,_,_,_,_,_,
	_,_,_,_,_,_,_,_,_,_,_,_,_,_,_,_,_,

	_,_,_,d,d,d,d,d,d,d,d,d,_,_,_,_,_,
	_,_,_,_,d,d,d,d,_,_,d,_,_,_,_,_,_,
	_,_,_,_,_,_,_,_,_,_,_,_,_,_,_,_,_,
	_,_,_,_,_,_,_,_,_,_,_,_,_,_,_,_,_,
	_,_,_,_,_,_,_,_,_,_,_,_,_,_,_,_,_,

	_,_,d,d,d,d,d,d,d,d,d,d,d,d,_,_,_,
	_,_,_,d,s,s,s,s,d,d,s,d,d,_,_,_,_,
	_,_,_,_,s,s,s,s,_,_,s,_,_,_,_,_,_,
	_,_,_,_,_,_,_,_,_,_,_,_,_,_,_,_,_,
	_,_,_,_,_,_,_,_,_,_,_,_,_,_,_,_,_,

	_,d,d,d,d,d,d,d,d,d,d,d,d,d,d,_,_,
	_,_,d,s,o,o,o,o,s,s,o,s,s,d,_,_,_,
	_,_,_,s,f,f,s,f,s,s,f,s,s,_,_,_,_,
	_,_,_,_,s,s,_,s,_,_,s,_,_,_,_,_,_,
	_,_,_,_,_,_,_,_,_,_,_,_,_,_,_,_,_,

	d,d,d,d,d,d,d,d,d,d,d,d,d,d,d,d,_,
	_,d,s,o,s,s,s,s,o,o,s,o,o,s,d,_,_,
	_,_,s,l,l,l,l,f,s,f,f,l,l,s,_,_,_,
	_,_,_,s,f,f,s,s,o,s,o,s,s,_,_,_,_,
	_,_,_,_,o,o,o,_,_,_,o,_,_,_,_,_,_,

	d,d,d,d,d,d,d,d,d,d,d,d,d,d,d,d,d,
	_,d,s,o,s,o,o,o,s,s,o,s,s,o,s,d,_,
	_,_,s,f,l,l,l,l,l,l,l,l,l,l,s,_,_,
	_,_,_,s,f,f,f,f,f,f,l,f,l,s,_,_,_,
	_,_,_,_,o,_,_,o,o,o,_,o,o,_,_,_,_,

    d,d,d,d,d,d,d,d,d,d,d,d,d,d,d,d,d,
	_,d,s,o,s,o,s,s,o,o,s,o,s,o,s,d,_,
	_,_,s,s,l,l,l,l,l,l,l,l,l,l,s,_,_,
	_,_,_,_,o,f,f,f,f,f,f,f,l,s,_,_,_,
	_,_,_,_,_,_,_,_,_,_,_,_,o,_,_,_,_,

	d,d,d,d,d,d,d,d,d,d,d,d,d,d,d,d,d,
	_,_,d,s,o,s,o,s,s,s,s,o,s,o,s,d,_,
	_,_,_,s,l,l,l,l,l,l,l,l,l,l,s,_,_,
	_,_,_,s,f,f,f,f,f,f,f,f,l,s,_,_,_,
	_,_,_,_,o,_,_,_,_,_,_,_,s,_,_,_,_,

	d,d,d,d,d,d,d,d,d,d,d,d,d,d,d,d,d,
	_,d,s,o,s,o,o,o,o,o,o,s,o,s,d,_,_,
	_,_,s,l,l,l,l,l,l,l,l,l,l,s,_,_,_,
	_,_,_,s,f,f,f,f,f,f,f,l,s,_,_,_,_,
	_,_,_,_,o,_,_,_,_,_,_,_,o,_,_,_,_,

	d,d,d,d,d,d,d,d,d,d,d,d,d,d,d,d,d,
	_,d,s,o,s,s,s,s,s,s,o,s,o,s,d,_,_,
	_,_,s,l,l,l,l,l,l,l,l,l,l,s,_,_,_,
	_,_,_,s,f,f,f,f,l,l,f,l,s,_,_,_,_,
	_,_,_,_,o,o,_,_,_,o,_,o,_,_,_,_,_,

	_,d,d,d,d,d,d,d,d,d,d,d,d,d,d,_,_,
	_,_,d,s,o,o,o,o,o,o,s,o,s,d,_,_,_,
	_,_,_,s,s,l,f,f,f,f,l,l,s,_,_,_,_,
	_,_,_,_,s,s,s,s,s,s,f,s,_,_,_,_,_,
	_,_,_,_,_,s,o,o,o,_,s,_,_,_,_,_,_,

	_,_,d,d,d,d,d,d,d,d,d,d,d,d,_,_,_,
	_,_,_,d,s,s,s,s,s,s,o,s,d,_,_,_,_,
	_,_,_,_,s,s,s,s,s,s,l,s,_,_,_,_,_,
	_,_,_,_,_,_,_,_,_,_,s,_,_,_,_,_,_,
	_,_,_,_,_,_,_,_,_,_,_,_,_,_,_,_,_,

	_,_,_,d,d,d,d,d,d,d,d,d,d,d,_,_,_,
	_,_,_,_,d,d,d,d,d,d,s,s,d,_,_,_,_,
	_,_,_,_,_,_,_,_,_,_,s,s,_,_,_,_,_,
	_,_,_,_,_,_,_,_,_,_,_,_,_,_,_,_,_,
	_,_,_,_,_,_,_,_,_,_,_,_,_,_,_,_,_,

	_,_,_,_,_,_,d,d,d,d,d,d,d,_,_,_,_,
	_,_,_,_,_,_,_,_,_,_,d,d,_,_,_,_,_,
	_,_,_,_,_,_,_,_,_,_,_,_,_,_,_,_,_,
	_,_,_,_,_,_,_,_,_,_,_,_,_,_,_,_,_,
	_,_,_,_,_,_,_,_,_,_,_,_,_,_,_,_,_,

	_,_,_,_,_,_,d,d,d,d,_,_,_,_,_,_,_,
	_,_,_,_,_,_,_,_,_,_,_,_,_,_,_,_,_,
	_,_,_,_,_,_,_,_,_,_,_,_,_,_,_,_,_,
	_,_,_,_,_,_,_,_,_,_,_,_,_,_,_,_,_,
	_,_,_,_,_,_,_,_,_,_,_,_,_,_,_,_,_,

	}
}

local _ = {name = "air", prob = 0}
local d = {name = "chemistry:stone", prob = 255}
local s = {name = "chemistry:stone_cobble_glow2", prob = 255, force_place = true}
local l = {name = "chemistry:mcopper", prob = 255, force_place = true}
local f = {name = "chemistry:mcopper_flowing", prob = 255}
local o = {name = "default:copperblock", prob = 215}

chemistry.metal_volcano2 = {

	size = {x = 17, y = 5, z = 15},

	yslice_prob = {
		{ypos = 0, prob = 127},
		{ypos = 1, prob = 127},
	},

	data = {

		_,_,_,_,_,_,d,d,d,d,_,_,_,_,_,_,_,
		_,_,_,_,_,_,_,_,_,_,_,_,_,_,_,_,_,
		_,_,_,_,_,_,_,_,_,_,_,_,_,_,_,_,_,
		_,_,_,_,_,_,_,_,_,_,_,_,_,_,_,_,_,
		_,_,_,_,_,_,_,_,_,_,_,_,_,_,_,_,_,
	
		_,_,_,d,d,d,d,d,d,d,d,d,_,_,_,_,_,
		_,_,_,_,d,d,d,d,_,_,d,_,_,_,_,_,_,
		_,_,_,_,_,_,_,_,_,_,_,_,_,_,_,_,_,
		_,_,_,_,_,_,_,_,_,_,_,_,_,_,_,_,_,
		_,_,_,_,_,_,_,_,_,_,_,_,_,_,_,_,_,
	
		_,_,d,d,d,d,d,d,d,d,d,d,d,d,_,_,_,
		_,_,_,d,s,s,s,s,d,d,s,d,d,_,_,_,_,
		_,_,_,_,s,s,s,s,_,_,s,_,_,_,_,_,_,
		_,_,_,_,_,_,_,_,_,_,_,_,_,_,_,_,_,
		_,_,_,_,_,_,_,_,_,_,_,_,_,_,_,_,_,
	
		_,d,d,d,d,d,d,d,d,d,d,d,d,d,d,_,_,
		_,_,d,s,o,o,o,o,s,s,o,s,s,d,_,_,_,
		_,_,_,s,f,f,s,f,s,s,f,s,s,_,_,_,_,
		_,_,_,_,s,s,_,s,_,_,s,_,_,_,_,_,_,
		_,_,_,_,_,_,_,_,_,_,_,_,_,_,_,_,_,
	
		d,d,d,d,d,d,d,d,d,d,d,d,d,d,d,d,_,
		_,d,s,o,s,s,s,s,o,o,s,o,o,s,d,_,_,
		_,_,s,l,l,l,l,f,s,f,f,l,l,s,_,_,_,
		_,_,_,s,f,f,s,s,o,s,o,s,s,_,_,_,_,
		_,_,_,_,o,o,o,_,_,_,o,_,_,_,_,_,_,
	
		d,d,d,d,d,d,d,d,d,d,d,d,d,d,d,d,d,
		_,d,s,o,s,o,o,o,s,s,o,s,s,o,s,d,_,
		_,_,s,f,l,l,l,l,l,l,l,l,l,l,s,_,_,
		_,_,_,s,f,f,f,f,f,f,l,f,l,s,_,_,_,
		_,_,_,_,o,_,_,o,o,o,_,o,o,_,_,_,_,
	
		d,d,d,d,d,d,d,d,d,d,d,d,d,d,d,d,d,
		_,d,s,o,s,o,s,s,o,o,s,o,s,o,s,d,_,
		_,_,s,s,l,l,l,l,l,l,l,l,l,l,s,_,_,
		_,_,_,_,o,f,f,f,f,f,f,f,l,s,_,_,_,
		_,_,_,_,_,_,_,_,_,_,_,_,o,_,_,_,_,
	
		d,d,d,d,d,d,d,d,d,d,d,d,d,d,d,d,d,
		_,_,d,s,o,s,o,s,s,s,s,o,s,o,s,d,_,
		_,_,_,s,l,l,l,l,l,l,l,l,l,l,s,_,_,
		_,_,_,s,f,f,f,f,f,f,f,f,l,s,_,_,_,
		_,_,_,_,o,_,_,_,_,_,_,_,s,_,_,_,_,
	
		d,d,d,d,d,d,d,d,d,d,d,d,d,d,d,d,d,
		_,d,s,o,s,o,o,o,o,o,o,s,o,s,d,_,_,
		_,_,s,l,l,l,l,l,l,l,l,l,l,s,_,_,_,
		_,_,_,s,f,f,f,f,f,f,f,l,s,_,_,_,_,
		_,_,_,_,o,_,_,_,_,_,_,_,o,_,_,_,_,
	
		d,d,d,d,d,d,d,d,d,d,d,d,d,d,d,d,d,
		_,d,s,o,s,s,s,s,s,s,o,s,o,s,d,_,_,
		_,_,s,l,l,l,l,l,l,l,l,l,l,s,_,_,_,
		_,_,_,s,f,f,f,f,l,l,f,l,s,_,_,_,_,
		_,_,_,_,o,o,_,_,_,o,_,o,_,_,_,_,_,
	
		_,d,d,d,d,d,d,d,d,d,d,d,d,d,d,_,_,
		_,_,d,s,o,o,o,o,o,o,s,o,s,d,_,_,_,
		_,_,_,s,s,l,f,f,f,f,l,l,s,_,_,_,_,
		_,_,_,_,s,s,s,s,s,s,f,s,_,_,_,_,_,
		_,_,_,_,_,s,o,o,o,_,s,_,_,_,_,_,_,
	
		_,_,d,d,d,d,d,d,d,d,d,d,d,d,_,_,_,
		_,_,_,d,s,s,s,s,s,s,o,s,d,_,_,_,_,
		_,_,_,_,s,s,s,s,s,s,l,s,_,_,_,_,_,
		_,_,_,_,_,_,_,_,_,_,s,_,_,_,_,_,_,
		_,_,_,_,_,_,_,_,_,_,_,_,_,_,_,_,_,
	
		_,_,_,d,d,d,d,d,d,d,d,d,d,d,_,_,_,
		_,_,_,_,d,d,d,d,d,d,s,s,d,_,_,_,_,
		_,_,_,_,_,_,_,_,_,_,s,s,_,_,_,_,_,
		_,_,_,_,_,_,_,_,_,_,_,_,_,_,_,_,_,
		_,_,_,_,_,_,_,_,_,_,_,_,_,_,_,_,_,
	
		_,_,_,_,_,_,d,d,d,d,d,d,d,_,_,_,_,
		_,_,_,_,_,_,_,_,_,_,d,d,_,_,_,_,_,
		_,_,_,_,_,_,_,_,_,_,_,_,_,_,_,_,_,
		_,_,_,_,_,_,_,_,_,_,_,_,_,_,_,_,_,
		_,_,_,_,_,_,_,_,_,_,_,_,_,_,_,_,_,
	
		_,_,_,_,_,_,d,d,d,d,_,_,_,_,_,_,_,
		_,_,_,_,_,_,_,_,_,_,_,_,_,_,_,_,_,
		_,_,_,_,_,_,_,_,_,_,_,_,_,_,_,_,_,
		_,_,_,_,_,_,_,_,_,_,_,_,_,_,_,_,_,
		_,_,_,_,_,_,_,_,_,_,_,_,_,_,_,_,_,
	
	}
}

local _ = {name = "air", prob = 0}
local d = {name = "chemistry:stone", prob = 255}
local s = {name = "chemistry:stone_cobble_glow3", prob = 255, force_place = true}
local l = {name = "chemistry:mtin", prob = 255, force_place = true}
local f = {name = "chemistry:mtin_flowing", prob = 255}
local o = {name = "default:tinblock", prob = 215}

chemistry.metal_volcano3 = {

	size = {x = 17, y = 5, z = 15},

	yslice_prob = {
		{ypos = 0, prob = 127},
		{ypos = 1, prob = 127},
	},

	data = {

		_,_,_,_,_,_,d,d,d,d,_,_,_,_,_,_,_,
		_,_,_,_,_,_,_,_,_,_,_,_,_,_,_,_,_,
		_,_,_,_,_,_,_,_,_,_,_,_,_,_,_,_,_,
		_,_,_,_,_,_,_,_,_,_,_,_,_,_,_,_,_,
		_,_,_,_,_,_,_,_,_,_,_,_,_,_,_,_,_,
	
		_,_,_,d,d,d,d,d,d,d,d,d,_,_,_,_,_,
		_,_,_,_,d,d,d,d,_,_,d,_,_,_,_,_,_,
		_,_,_,_,_,_,_,_,_,_,_,_,_,_,_,_,_,
		_,_,_,_,_,_,_,_,_,_,_,_,_,_,_,_,_,
		_,_,_,_,_,_,_,_,_,_,_,_,_,_,_,_,_,
	
		_,_,d,d,d,d,d,d,d,d,d,d,d,d,_,_,_,
		_,_,_,d,s,s,s,s,d,d,s,d,d,_,_,_,_,
		_,_,_,_,s,s,s,s,_,_,s,_,_,_,_,_,_,
		_,_,_,_,_,_,_,_,_,_,_,_,_,_,_,_,_,
		_,_,_,_,_,_,_,_,_,_,_,_,_,_,_,_,_,
	
		_,d,d,d,d,d,d,d,d,d,d,d,d,d,d,_,_,
		_,_,d,s,o,o,o,o,s,s,o,s,s,d,_,_,_,
		_,_,_,s,f,f,s,f,s,s,f,s,s,_,_,_,_,
		_,_,_,_,s,s,_,s,_,_,s,_,_,_,_,_,_,
		_,_,_,_,_,_,_,_,_,_,_,_,_,_,_,_,_,
	
		d,d,d,d,d,d,d,d,d,d,d,d,d,d,d,d,_,
		_,d,s,o,s,s,s,s,o,o,s,o,o,s,d,_,_,
		_,_,s,l,l,l,l,f,s,f,f,l,l,s,_,_,_,
		_,_,_,s,f,f,s,s,o,s,o,s,s,_,_,_,_,
		_,_,_,_,o,o,o,_,_,_,o,_,_,_,_,_,_,
	
		d,d,d,d,d,d,d,d,d,d,d,d,d,d,d,d,d,
		_,d,s,o,s,o,o,o,s,s,o,s,s,o,s,d,_,
		_,_,s,f,l,l,l,l,l,l,l,l,l,l,s,_,_,
		_,_,_,s,f,f,f,f,f,f,l,f,l,s,_,_,_,
		_,_,_,_,o,_,_,o,o,o,_,o,o,_,_,_,_,
	
		d,d,d,d,d,d,d,d,d,d,d,d,d,d,d,d,d,
		_,d,s,o,s,o,s,s,o,o,s,o,s,o,s,d,_,
		_,_,s,s,l,l,l,l,l,l,l,l,l,l,s,_,_,
		_,_,_,_,o,f,f,f,f,f,f,f,l,s,_,_,_,
		_,_,_,_,_,_,_,_,_,_,_,_,o,_,_,_,_,
	
		d,d,d,d,d,d,d,d,d,d,d,d,d,d,d,d,d,
		_,_,d,s,o,s,o,s,s,s,s,o,s,o,s,d,_,
		_,_,_,s,l,l,l,l,l,l,l,l,l,l,s,_,_,
		_,_,_,s,f,f,f,f,f,f,f,f,l,s,_,_,_,
		_,_,_,_,o,_,_,_,_,_,_,_,s,_,_,_,_,
	
		d,d,d,d,d,d,d,d,d,d,d,d,d,d,d,d,d,
		_,d,s,o,s,o,o,o,o,o,o,s,o,s,d,_,_,
		_,_,s,l,l,l,l,l,l,l,l,l,l,s,_,_,_,
		_,_,_,s,f,f,f,f,f,f,f,l,s,_,_,_,_,
		_,_,_,_,o,_,_,_,_,_,_,_,o,_,_,_,_,
	
		d,d,d,d,d,d,d,d,d,d,d,d,d,d,d,d,d,
		_,d,s,o,s,s,s,s,s,s,o,s,o,s,d,_,_,
		_,_,s,l,l,l,l,l,l,l,l,l,l,s,_,_,_,
		_,_,_,s,f,f,f,f,l,l,f,l,s,_,_,_,_,
		_,_,_,_,o,o,_,_,_,o,_,o,_,_,_,_,_,
	
		_,d,d,d,d,d,d,d,d,d,d,d,d,d,d,_,_,
		_,_,d,s,o,o,o,o,o,o,s,o,s,d,_,_,_,
		_,_,_,s,s,l,f,f,f,f,l,l,s,_,_,_,_,
		_,_,_,_,s,s,s,s,s,s,f,s,_,_,_,_,_,
		_,_,_,_,_,s,o,o,o,_,s,_,_,_,_,_,_,
	
		_,_,d,d,d,d,d,d,d,d,d,d,d,d,_,_,_,
		_,_,_,d,s,s,s,s,s,s,o,s,d,_,_,_,_,
		_,_,_,_,s,s,s,s,s,s,l,s,_,_,_,_,_,
		_,_,_,_,_,_,_,_,_,_,s,_,_,_,_,_,_,
		_,_,_,_,_,_,_,_,_,_,_,_,_,_,_,_,_,
	
		_,_,_,d,d,d,d,d,d,d,d,d,d,d,_,_,_,
		_,_,_,_,d,d,d,d,d,d,s,s,d,_,_,_,_,
		_,_,_,_,_,_,_,_,_,_,s,s,_,_,_,_,_,
		_,_,_,_,_,_,_,_,_,_,_,_,_,_,_,_,_,
		_,_,_,_,_,_,_,_,_,_,_,_,_,_,_,_,_,
	
		_,_,_,_,_,_,d,d,d,d,d,d,d,_,_,_,_,
		_,_,_,_,_,_,_,_,_,_,d,d,_,_,_,_,_,
		_,_,_,_,_,_,_,_,_,_,_,_,_,_,_,_,_,
		_,_,_,_,_,_,_,_,_,_,_,_,_,_,_,_,_,
		_,_,_,_,_,_,_,_,_,_,_,_,_,_,_,_,_,
	
		_,_,_,_,_,_,d,d,d,d,_,_,_,_,_,_,_,
		_,_,_,_,_,_,_,_,_,_,_,_,_,_,_,_,_,
		_,_,_,_,_,_,_,_,_,_,_,_,_,_,_,_,_,
		_,_,_,_,_,_,_,_,_,_,_,_,_,_,_,_,_,
		_,_,_,_,_,_,_,_,_,_,_,_,_,_,_,_,_,
	
	}
}

local _ = {name = "air", prob = 0}
local d = {name = "chemistry:stone", prob = 255}
local s = {name = "chemistry:stone_cobble_glow2", prob = 255, force_place = true}
local l = {name = "chemistry:mtitanium", prob = 255, force_place = true}
local f = {name = "chemistry:mtitanium_flowing", prob = 255}
local o = {name = "chemistry:titanium_block", prob = 215}

chemistry.metal_volcano4 = {

	size = {x = 17, y = 5, z = 15},

	yslice_prob = {
		{ypos = 0, prob = 127},
		{ypos = 1, prob = 127},
	},

	data = {

		_,_,_,_,_,_,d,d,d,d,_,_,_,_,_,_,_,
		_,_,_,_,_,_,_,_,_,_,_,_,_,_,_,_,_,
		_,_,_,_,_,_,_,_,_,_,_,_,_,_,_,_,_,
		_,_,_,_,_,_,_,_,_,_,_,_,_,_,_,_,_,
		_,_,_,_,_,_,_,_,_,_,_,_,_,_,_,_,_,
	
		_,_,_,d,d,d,d,d,d,d,d,d,_,_,_,_,_,
		_,_,_,_,d,d,d,d,_,_,d,_,_,_,_,_,_,
		_,_,_,_,_,_,_,_,_,_,_,_,_,_,_,_,_,
		_,_,_,_,_,_,_,_,_,_,_,_,_,_,_,_,_,
		_,_,_,_,_,_,_,_,_,_,_,_,_,_,_,_,_,
	
		_,_,d,d,d,d,d,d,d,d,d,d,d,d,_,_,_,
		_,_,_,d,s,s,s,s,d,d,s,d,d,_,_,_,_,
		_,_,_,_,s,s,s,s,_,_,s,_,_,_,_,_,_,
		_,_,_,_,_,_,_,_,_,_,_,_,_,_,_,_,_,
		_,_,_,_,_,_,_,_,_,_,_,_,_,_,_,_,_,
	
		_,d,d,d,d,d,d,d,d,d,d,d,d,d,d,_,_,
		_,_,d,s,o,o,o,o,s,s,o,s,s,d,_,_,_,
		_,_,_,s,f,f,s,f,s,s,f,s,s,_,_,_,_,
		_,_,_,_,s,s,_,s,_,_,s,_,_,_,_,_,_,
		_,_,_,_,_,_,_,_,_,_,_,_,_,_,_,_,_,
	
		d,d,d,d,d,d,d,d,d,d,d,d,d,d,d,d,_,
		_,d,s,o,s,s,s,s,o,o,s,o,o,s,d,_,_,
		_,_,s,l,l,l,l,f,s,f,f,l,l,s,_,_,_,
		_,_,_,s,f,f,s,s,o,s,o,s,s,_,_,_,_,
		_,_,_,_,o,o,o,_,_,_,o,_,_,_,_,_,_,
	
		d,d,d,d,d,d,d,d,d,d,d,d,d,d,d,d,d,
		_,d,s,o,s,o,o,o,s,s,o,s,s,o,s,d,_,
		_,_,s,f,l,l,l,l,l,l,l,l,l,l,s,_,_,
		_,_,_,s,f,f,f,f,f,f,l,f,l,s,_,_,_,
		_,_,_,_,o,_,_,o,o,o,_,o,o,_,_,_,_,
	
		d,d,d,d,d,d,d,d,d,d,d,d,d,d,d,d,d,
		_,d,s,o,s,o,s,s,o,o,s,o,s,o,s,d,_,
		_,_,s,s,l,l,l,l,l,l,l,l,l,l,s,_,_,
		_,_,_,_,o,f,f,f,f,f,f,f,l,s,_,_,_,
		_,_,_,_,_,_,_,_,_,_,_,_,o,_,_,_,_,
	
		d,d,d,d,d,d,d,d,d,d,d,d,d,d,d,d,d,
		_,_,d,s,o,s,o,s,s,s,s,o,s,o,s,d,_,
		_,_,_,s,l,l,l,l,l,l,l,l,l,l,s,_,_,
		_,_,_,s,f,f,f,f,f,f,f,f,l,s,_,_,_,
		_,_,_,_,o,_,_,_,_,_,_,_,s,_,_,_,_,
	
		d,d,d,d,d,d,d,d,d,d,d,d,d,d,d,d,d,
		_,d,s,o,s,o,o,o,o,o,o,s,o,s,d,_,_,
		_,_,s,l,l,l,l,l,l,l,l,l,l,s,_,_,_,
		_,_,_,s,f,f,f,f,f,f,f,l,s,_,_,_,_,
		_,_,_,_,o,_,_,_,_,_,_,_,o,_,_,_,_,
	
		d,d,d,d,d,d,d,d,d,d,d,d,d,d,d,d,d,
		_,d,s,o,s,s,s,s,s,s,o,s,o,s,d,_,_,
		_,_,s,l,l,l,l,l,l,l,l,l,l,s,_,_,_,
		_,_,_,s,f,f,f,f,l,l,f,l,s,_,_,_,_,
		_,_,_,_,o,o,_,_,_,o,_,o,_,_,_,_,_,
	
		_,d,d,d,d,d,d,d,d,d,d,d,d,d,d,_,_,
		_,_,d,s,o,o,o,o,o,o,s,o,s,d,_,_,_,
		_,_,_,s,s,l,f,f,f,f,l,l,s,_,_,_,_,
		_,_,_,_,s,s,s,s,s,s,f,s,_,_,_,_,_,
		_,_,_,_,_,s,o,o,o,_,s,_,_,_,_,_,_,
	
		_,_,d,d,d,d,d,d,d,d,d,d,d,d,_,_,_,
		_,_,_,d,s,s,s,s,s,s,o,s,d,_,_,_,_,
		_,_,_,_,s,s,s,s,s,s,l,s,_,_,_,_,_,
		_,_,_,_,_,_,_,_,_,_,s,_,_,_,_,_,_,
		_,_,_,_,_,_,_,_,_,_,_,_,_,_,_,_,_,
	
		_,_,_,d,d,d,d,d,d,d,d,d,d,d,_,_,_,
		_,_,_,_,d,d,d,d,d,d,s,s,d,_,_,_,_,
		_,_,_,_,_,_,_,_,_,_,s,s,_,_,_,_,_,
		_,_,_,_,_,_,_,_,_,_,_,_,_,_,_,_,_,
		_,_,_,_,_,_,_,_,_,_,_,_,_,_,_,_,_,
	
		_,_,_,_,_,_,d,d,d,d,d,d,d,_,_,_,_,
		_,_,_,_,_,_,_,_,_,_,d,d,_,_,_,_,_,
		_,_,_,_,_,_,_,_,_,_,_,_,_,_,_,_,_,
		_,_,_,_,_,_,_,_,_,_,_,_,_,_,_,_,_,
		_,_,_,_,_,_,_,_,_,_,_,_,_,_,_,_,_,
	
		_,_,_,_,_,_,d,d,d,d,_,_,_,_,_,_,_,
		_,_,_,_,_,_,_,_,_,_,_,_,_,_,_,_,_,
		_,_,_,_,_,_,_,_,_,_,_,_,_,_,_,_,_,
		_,_,_,_,_,_,_,_,_,_,_,_,_,_,_,_,_,
		_,_,_,_,_,_,_,_,_,_,_,_,_,_,_,_,_,
	
	}
}

local _ = {name = "air", prob = 0}
local d = {name = "chemistry:stone", prob = 255}
local s = {name = "chemistry:stone_cobble_glow2", prob = 255, force_place = true}
local l = {name = "chemistry:mosmium", prob = 255, force_place = true}
local f = {name = "chemistry:mosmium_flowing", prob = 255}
local o = {name = "chemistry:osmium_block", prob = 215}

chemistry.metal_volcano5 = {

	size = {x = 17, y = 5, z = 15},

	yslice_prob = {
		{ypos = 0, prob = 127},
		{ypos = 1, prob = 127},
	},

	data = {

		_,_,_,_,_,_,d,d,d,d,_,_,_,_,_,_,_,
		_,_,_,_,_,_,_,_,_,_,_,_,_,_,_,_,_,
		_,_,_,_,_,_,_,_,_,_,_,_,_,_,_,_,_,
		_,_,_,_,_,_,_,_,_,_,_,_,_,_,_,_,_,
		_,_,_,_,_,_,_,_,_,_,_,_,_,_,_,_,_,
	
		_,_,_,d,d,d,d,d,d,d,d,d,_,_,_,_,_,
		_,_,_,_,d,d,d,d,_,_,d,_,_,_,_,_,_,
		_,_,_,_,_,_,_,_,_,_,_,_,_,_,_,_,_,
		_,_,_,_,_,_,_,_,_,_,_,_,_,_,_,_,_,
		_,_,_,_,_,_,_,_,_,_,_,_,_,_,_,_,_,
	
		_,_,d,d,d,d,d,d,d,d,d,d,d,d,_,_,_,
		_,_,_,d,s,s,s,s,d,d,s,d,d,_,_,_,_,
		_,_,_,_,s,s,s,s,_,_,s,_,_,_,_,_,_,
		_,_,_,_,_,_,_,_,_,_,_,_,_,_,_,_,_,
		_,_,_,_,_,_,_,_,_,_,_,_,_,_,_,_,_,
	
		_,d,d,d,d,d,d,d,d,d,d,d,d,d,d,_,_,
		_,_,d,s,o,o,o,o,s,s,o,s,s,d,_,_,_,
		_,_,_,s,f,f,s,f,s,s,f,s,s,_,_,_,_,
		_,_,_,_,s,s,_,s,_,_,s,_,_,_,_,_,_,
		_,_,_,_,_,_,_,_,_,_,_,_,_,_,_,_,_,
	
		d,d,d,d,d,d,d,d,d,d,d,d,d,d,d,d,_,
		_,d,s,o,s,s,s,s,o,o,s,o,o,s,d,_,_,
		_,_,s,l,l,l,l,f,s,f,f,l,l,s,_,_,_,
		_,_,_,s,f,f,s,s,o,s,o,s,s,_,_,_,_,
		_,_,_,_,o,o,o,_,_,_,o,_,_,_,_,_,_,
	
		d,d,d,d,d,d,d,d,d,d,d,d,d,d,d,d,d,
		_,d,s,o,s,o,o,o,s,s,o,s,s,o,s,d,_,
		_,_,s,f,l,l,l,l,l,l,l,l,l,l,s,_,_,
		_,_,_,s,f,f,f,f,f,f,l,f,l,s,_,_,_,
		_,_,_,_,o,_,_,o,o,o,_,o,o,_,_,_,_,
	
		d,d,d,d,d,d,d,d,d,d,d,d,d,d,d,d,d,
		_,d,s,o,s,o,s,s,o,o,s,o,s,o,s,d,_,
		_,_,s,s,l,l,l,l,l,l,l,l,l,l,s,_,_,
		_,_,_,_,o,f,f,f,f,f,f,f,l,s,_,_,_,
		_,_,_,_,_,_,_,_,_,_,_,_,o,_,_,_,_,
	
		d,d,d,d,d,d,d,d,d,d,d,d,d,d,d,d,d,
		_,_,d,s,o,s,o,s,s,s,s,o,s,o,s,d,_,
		_,_,_,s,l,l,l,l,l,l,l,l,l,l,s,_,_,
		_,_,_,s,f,f,f,f,f,f,f,f,l,s,_,_,_,
		_,_,_,_,o,_,_,_,_,_,_,_,s,_,_,_,_,
	
		d,d,d,d,d,d,d,d,d,d,d,d,d,d,d,d,d,
		_,d,s,o,s,o,o,o,o,o,o,s,o,s,d,_,_,
		_,_,s,l,l,l,l,l,l,l,l,l,l,s,_,_,_,
		_,_,_,s,f,f,f,f,f,f,f,l,s,_,_,_,_,
		_,_,_,_,o,_,_,_,_,_,_,_,o,_,_,_,_,
	
		d,d,d,d,d,d,d,d,d,d,d,d,d,d,d,d,d,
		_,d,s,o,s,s,s,s,s,s,o,s,o,s,d,_,_,
		_,_,s,l,l,l,l,l,l,l,l,l,l,s,_,_,_,
		_,_,_,s,f,f,f,f,l,l,f,l,s,_,_,_,_,
		_,_,_,_,o,o,_,_,_,o,_,o,_,_,_,_,_,
	
		_,d,d,d,d,d,d,d,d,d,d,d,d,d,d,_,_,
		_,_,d,s,o,o,o,o,o,o,s,o,s,d,_,_,_,
		_,_,_,s,s,l,f,f,f,f,l,l,s,_,_,_,_,
		_,_,_,_,s,s,s,s,s,s,f,s,_,_,_,_,_,
		_,_,_,_,_,s,o,o,o,_,s,_,_,_,_,_,_,
	
		_,_,d,d,d,d,d,d,d,d,d,d,d,d,_,_,_,
		_,_,_,d,s,s,s,s,s,s,o,s,d,_,_,_,_,
		_,_,_,_,s,s,s,s,s,s,l,s,_,_,_,_,_,
		_,_,_,_,_,_,_,_,_,_,s,_,_,_,_,_,_,
		_,_,_,_,_,_,_,_,_,_,_,_,_,_,_,_,_,
	
		_,_,_,d,d,d,d,d,d,d,d,d,d,d,_,_,_,
		_,_,_,_,d,d,d,d,d,d,s,s,d,_,_,_,_,
		_,_,_,_,_,_,_,_,_,_,s,s,_,_,_,_,_,
		_,_,_,_,_,_,_,_,_,_,_,_,_,_,_,_,_,
		_,_,_,_,_,_,_,_,_,_,_,_,_,_,_,_,_,
	
		_,_,_,_,_,_,d,d,d,d,d,d,d,_,_,_,_,
		_,_,_,_,_,_,_,_,_,_,d,d,_,_,_,_,_,
		_,_,_,_,_,_,_,_,_,_,_,_,_,_,_,_,_,
		_,_,_,_,_,_,_,_,_,_,_,_,_,_,_,_,_,
		_,_,_,_,_,_,_,_,_,_,_,_,_,_,_,_,_,
	
		_,_,_,_,_,_,d,d,d,d,_,_,_,_,_,_,_,
		_,_,_,_,_,_,_,_,_,_,_,_,_,_,_,_,_,
		_,_,_,_,_,_,_,_,_,_,_,_,_,_,_,_,_,
		_,_,_,_,_,_,_,_,_,_,_,_,_,_,_,_,_,
		_,_,_,_,_,_,_,_,_,_,_,_,_,_,_,_,_,
	
	}
}

local _ = {name = "air", prob = 0}
local d = {name = "chemistry:stone", prob = 255}
local s = {name = "chemistry:stone_cobble_glow1", prob = 255, force_place = true}
local l = {name = "chemistry:st_lava", prob = 255, force_place = true}
local f = {name = "chemistry:st_lava_flowing", prob = 255}
local o = {name = "chemistry:obsidian", prob = 215}

chemistry.st_volcano = {

	size = {x = 17, y = 5, z = 15},

	yslice_prob = {
		{ypos = 0, prob = 127},
		{ypos = 1, prob = 127},
	},

	data = {

		_,_,_,_,_,_,d,d,d,d,_,_,_,_,_,_,_,
		_,_,_,_,_,_,_,_,_,_,_,_,_,_,_,_,_,
		_,_,_,_,_,_,_,_,_,_,_,_,_,_,_,_,_,
		_,_,_,_,_,_,_,_,_,_,_,_,_,_,_,_,_,
		_,_,_,_,_,_,_,_,_,_,_,_,_,_,_,_,_,
	
		_,_,_,d,d,d,d,d,d,d,d,d,_,_,_,_,_,
		_,_,_,_,d,d,d,d,_,_,d,_,_,_,_,_,_,
		_,_,_,_,_,_,_,_,_,_,_,_,_,_,_,_,_,
		_,_,_,_,_,_,_,_,_,_,_,_,_,_,_,_,_,
		_,_,_,_,_,_,_,_,_,_,_,_,_,_,_,_,_,
	
		_,_,d,d,d,d,d,d,d,d,d,d,d,d,_,_,_,
		_,_,_,d,s,s,s,s,d,d,s,d,d,_,_,_,_,
		_,_,_,_,s,s,s,s,_,_,s,_,_,_,_,_,_,
		_,_,_,_,_,_,_,_,_,_,_,_,_,_,_,_,_,
		_,_,_,_,_,_,_,_,_,_,_,_,_,_,_,_,_,
	
		_,d,d,d,d,d,d,d,d,d,d,d,d,d,d,_,_,
		_,_,d,s,o,o,o,o,s,s,o,s,s,d,_,_,_,
		_,_,_,s,f,f,s,f,s,s,f,s,s,_,_,_,_,
		_,_,_,_,s,s,_,s,_,_,s,_,_,_,_,_,_,
		_,_,_,_,_,_,_,_,_,_,_,_,_,_,_,_,_,
	
		d,d,d,d,d,d,d,d,d,d,d,d,d,d,d,d,_,
		_,d,s,o,s,s,s,s,o,o,s,o,o,s,d,_,_,
		_,_,s,l,l,l,l,f,s,f,f,l,l,s,_,_,_,
		_,_,_,s,f,f,s,s,o,s,o,s,s,_,_,_,_,
		_,_,_,_,o,o,o,_,_,_,o,_,_,_,_,_,_,
	
		d,d,d,d,d,d,d,d,d,d,d,d,d,d,d,d,d,
		_,d,s,o,s,o,o,o,s,s,o,s,s,o,s,d,_,
		_,_,s,f,l,l,l,l,l,l,l,l,l,l,s,_,_,
		_,_,_,s,f,f,f,f,f,f,l,f,l,s,_,_,_,
		_,_,_,_,o,_,_,o,o,o,_,o,o,_,_,_,_,
	
		d,d,d,d,d,d,d,d,d,d,d,d,d,d,d,d,d,
		_,d,s,o,s,o,s,s,o,o,s,o,s,o,s,d,_,
		_,_,s,s,l,l,l,l,l,l,l,l,l,l,s,_,_,
		_,_,_,_,o,f,f,f,f,f,f,f,l,s,_,_,_,
		_,_,_,_,_,_,_,_,_,_,_,_,o,_,_,_,_,
	
		d,d,d,d,d,d,d,d,d,d,d,d,d,d,d,d,d,
		_,_,d,s,o,s,o,s,s,s,s,o,s,o,s,d,_,
		_,_,_,s,l,l,l,l,l,l,l,l,l,l,s,_,_,
		_,_,_,s,f,f,f,f,f,f,f,f,l,s,_,_,_,
		_,_,_,_,o,_,_,_,_,_,_,_,s,_,_,_,_,
	
		d,d,d,d,d,d,d,d,d,d,d,d,d,d,d,d,d,
		_,d,s,o,s,o,o,o,o,o,o,s,o,s,d,_,_,
		_,_,s,l,l,l,l,l,l,l,l,l,l,s,_,_,_,
		_,_,_,s,f,f,f,f,f,f,f,l,s,_,_,_,_,
		_,_,_,_,o,_,_,_,_,_,_,_,o,_,_,_,_,
	
		d,d,d,d,d,d,d,d,d,d,d,d,d,d,d,d,d,
		_,d,s,o,s,s,s,s,s,s,o,s,o,s,d,_,_,
		_,_,s,l,l,l,l,l,l,l,l,l,l,s,_,_,_,
		_,_,_,s,f,f,f,f,l,l,f,l,s,_,_,_,_,
		_,_,_,_,o,o,_,_,_,o,_,o,_,_,_,_,_,
	
		_,d,d,d,d,d,d,d,d,d,d,d,d,d,d,_,_,
		_,_,d,s,o,o,o,o,o,o,s,o,s,d,_,_,_,
		_,_,_,s,s,l,f,f,f,f,l,l,s,_,_,_,_,
		_,_,_,_,s,s,s,s,s,s,f,s,_,_,_,_,_,
		_,_,_,_,_,s,o,o,o,_,s,_,_,_,_,_,_,
	
		_,_,d,d,d,d,d,d,d,d,d,d,d,d,_,_,_,
		_,_,_,d,s,s,s,s,s,s,o,s,d,_,_,_,_,
		_,_,_,_,s,s,s,s,s,s,l,s,_,_,_,_,_,
		_,_,_,_,_,_,_,_,_,_,s,_,_,_,_,_,_,
		_,_,_,_,_,_,_,_,_,_,_,_,_,_,_,_,_,
	
		_,_,_,d,d,d,d,d,d,d,d,d,d,d,_,_,_,
		_,_,_,_,d,d,d,d,d,d,s,s,d,_,_,_,_,
		_,_,_,_,_,_,_,_,_,_,s,s,_,_,_,_,_,
		_,_,_,_,_,_,_,_,_,_,_,_,_,_,_,_,_,
		_,_,_,_,_,_,_,_,_,_,_,_,_,_,_,_,_,
	
		_,_,_,_,_,_,d,d,d,d,d,d,d,_,_,_,_,
		_,_,_,_,_,_,_,_,_,_,d,d,_,_,_,_,_,
		_,_,_,_,_,_,_,_,_,_,_,_,_,_,_,_,_,
		_,_,_,_,_,_,_,_,_,_,_,_,_,_,_,_,_,
		_,_,_,_,_,_,_,_,_,_,_,_,_,_,_,_,_,
	
		_,_,_,_,_,_,d,d,d,d,_,_,_,_,_,_,_,
		_,_,_,_,_,_,_,_,_,_,_,_,_,_,_,_,_,
		_,_,_,_,_,_,_,_,_,_,_,_,_,_,_,_,_,
		_,_,_,_,_,_,_,_,_,_,_,_,_,_,_,_,_,
		_,_,_,_,_,_,_,_,_,_,_,_,_,_,_,_,_,
	
	}
}

